[2024-11-26T13:20:16.299+0000] {taskinstance.py:1083} INFO - Dependencies all met for <TaskInstance: data_processing.process_data manual__2024-11-26T13:20:14.030082+00:00 [queued]>
[2024-11-26T13:20:16.308+0000] {taskinstance.py:1083} INFO - Dependencies all met for <TaskInstance: data_processing.process_data manual__2024-11-26T13:20:14.030082+00:00 [queued]>
[2024-11-26T13:20:16.309+0000] {taskinstance.py:1279} INFO - 
--------------------------------------------------------------------------------
[2024-11-26T13:20:16.309+0000] {taskinstance.py:1280} INFO - Starting attempt 1 of 2
[2024-11-26T13:20:16.310+0000] {taskinstance.py:1281} INFO - 
--------------------------------------------------------------------------------
[2024-11-26T13:20:16.327+0000] {taskinstance.py:1300} INFO - Executing <Task(PythonOperator): process_data> on 2024-11-26 13:20:14.030082+00:00
[2024-11-26T13:20:16.336+0000] {standard_task_runner.py:55} INFO - Started process 123 to run task
[2024-11-26T13:20:16.339+0000] {standard_task_runner.py:82} INFO - Running: ['***', 'tasks', 'run', 'data_processing', 'process_data', 'manual__2024-11-26T13:20:14.030082+00:00', '--job-id', '27', '--raw', '--subdir', 'DAGS_FOLDER/data_processing_dag.py', '--cfg-path', '/tmp/tmp4zb0eni0']
[2024-11-26T13:20:16.342+0000] {standard_task_runner.py:83} INFO - Job 27: Subtask process_data
[2024-11-26T13:20:16.407+0000] {task_command.py:388} INFO - Running <TaskInstance: data_processing.process_data manual__2024-11-26T13:20:14.030082+00:00 [running]> on host 85d39f567857
[2024-11-26T13:20:16.467+0000] {taskinstance.py:1507} INFO - Exporting the following env vars:
AIRFLOW_CTX_DAG_OWNER=***
AIRFLOW_CTX_DAG_ID=data_processing
AIRFLOW_CTX_TASK_ID=process_data
AIRFLOW_CTX_EXECUTION_DATE=2024-11-26T13:20:14.030082+00:00
AIRFLOW_CTX_TRY_NUMBER=1
AIRFLOW_CTX_DAG_RUN_ID=manual__2024-11-26T13:20:14.030082+00:00
[2024-11-26T13:20:19.158+0000] {taskinstance.py:1768} ERROR - Task failed with exception
Traceback (most recent call last):
  File "/home/airflow/.local/lib/python3.8/site-packages/airflow/operators/python.py", line 175, in execute
    return_value = self.execute_callable()
  File "/home/airflow/.local/lib/python3.8/site-packages/airflow/operators/python.py", line 192, in execute_callable
    return self.python_callable(*self.op_args, **self.op_kwargs)
  File "/opt/airflow/dags/data_processing_dag.py", line 27, in process_data
    df_scaled = scaler.fit_transform(df)
  File "/home/airflow/.local/lib/python3.8/site-packages/sklearn/utils/_set_output.py", line 157, in wrapped
    data_to_wrap = f(self, X, *args, **kwargs)
  File "/home/airflow/.local/lib/python3.8/site-packages/sklearn/base.py", line 916, in fit_transform
    return self.fit(X, **fit_params).transform(X)
  File "/home/airflow/.local/lib/python3.8/site-packages/sklearn/preprocessing/_data.py", line 839, in fit
    return self.partial_fit(X, y, sample_weight)
  File "/home/airflow/.local/lib/python3.8/site-packages/sklearn/base.py", line 1152, in wrapper
    return fit_method(estimator, *args, **kwargs)
  File "/home/airflow/.local/lib/python3.8/site-packages/sklearn/preprocessing/_data.py", line 875, in partial_fit
    X = self._validate_data(
  File "/home/airflow/.local/lib/python3.8/site-packages/sklearn/base.py", line 605, in _validate_data
    out = check_array(X, input_name="X", **check_params)
  File "/home/airflow/.local/lib/python3.8/site-packages/sklearn/utils/validation.py", line 915, in check_array
    array = _asarray_with_order(array, order=order, dtype=dtype, xp=xp)
  File "/home/airflow/.local/lib/python3.8/site-packages/sklearn/utils/_array_api.py", line 380, in _asarray_with_order
    array = numpy.asarray(array, order=order, dtype=dtype)
  File "/home/airflow/.local/lib/python3.8/site-packages/pandas/core/generic.py", line 2070, in __array__
    return np.asarray(self._values, dtype=dtype)
ValueError: could not convert string to float: 'Pooja,Female,37,Ghaziabad,Working Professional,Teacher,,2,,,4,7-8 hours,Moderate,MA,No,6,2,No,No'
[2024-11-26T13:20:19.172+0000] {taskinstance.py:1318} INFO - Marking task as UP_FOR_RETRY. dag_id=data_processing, task_id=process_data, execution_date=20241126T132014, start_date=20241126T132016, end_date=20241126T132019
[2024-11-26T13:20:19.186+0000] {standard_task_runner.py:100} ERROR - Failed to execute job 27 for task process_data (could not convert string to float: 'Pooja,Female,37,Ghaziabad,Working Professional,Teacher,,2,,,4,7-8 hours,Moderate,MA,No,6,2,No,No'; 123)
[2024-11-26T13:20:19.201+0000] {local_task_job.py:208} INFO - Task exited with return code 1
[2024-11-26T13:20:19.217+0000] {taskinstance.py:2578} INFO - 0 downstream tasks scheduled from follow-on schedule check
