[2024-11-26T14:14:37.561+0000] {taskinstance.py:1083} INFO - Dependencies all met for <TaskInstance: data_split_google_sheets.split_data manual__2024-11-26T14:09:30.977878+00:00 [queued]>
[2024-11-26T14:14:37.568+0000] {taskinstance.py:1083} INFO - Dependencies all met for <TaskInstance: data_split_google_sheets.split_data manual__2024-11-26T14:09:30.977878+00:00 [queued]>
[2024-11-26T14:14:37.568+0000] {taskinstance.py:1279} INFO - 
--------------------------------------------------------------------------------
[2024-11-26T14:14:37.569+0000] {taskinstance.py:1280} INFO - Starting attempt 2 of 2
[2024-11-26T14:14:37.569+0000] {taskinstance.py:1281} INFO - 
--------------------------------------------------------------------------------
[2024-11-26T14:14:37.582+0000] {taskinstance.py:1300} INFO - Executing <Task(PythonOperator): split_data> on 2024-11-26 14:09:30.977878+00:00
[2024-11-26T14:14:37.590+0000] {standard_task_runner.py:55} INFO - Started process 95 to run task
[2024-11-26T14:14:37.592+0000] {standard_task_runner.py:82} INFO - Running: ['***', 'tasks', 'run', 'data_split_google_sheets', 'split_data', 'manual__2024-11-26T14:09:30.977878+00:00', '--job-id', '49', '--raw', '--subdir', 'DAGS_FOLDER/data_processing_dag.py', '--cfg-path', '/tmp/tmp1aaxf174']
[2024-11-26T14:14:37.595+0000] {standard_task_runner.py:83} INFO - Job 49: Subtask split_data
[2024-11-26T14:14:37.651+0000] {task_command.py:388} INFO - Running <TaskInstance: data_split_google_sheets.split_data manual__2024-11-26T14:09:30.977878+00:00 [running]> on host 35d2420ccfd7
[2024-11-26T14:14:37.712+0000] {taskinstance.py:1507} INFO - Exporting the following env vars:
AIRFLOW_CTX_DAG_OWNER=***
AIRFLOW_CTX_DAG_ID=data_split_google_sheets
AIRFLOW_CTX_TASK_ID=split_data
AIRFLOW_CTX_EXECUTION_DATE=2024-11-26T14:09:30.977878+00:00
AIRFLOW_CTX_TRY_NUMBER=2
AIRFLOW_CTX_DAG_RUN_ID=manual__2024-11-26T14:09:30.977878+00:00
[2024-11-26T14:14:37.724+0000] {taskinstance.py:1768} ERROR - Task failed with exception
Traceback (most recent call last):
  File "/home/airflow/.local/lib/python3.8/site-packages/airflow/operators/python.py", line 175, in execute
    return_value = self.execute_callable()
  File "/home/airflow/.local/lib/python3.8/site-packages/airflow/operators/python.py", line 192, in execute_callable
    return self.python_callable(*self.op_args, **self.op_kwargs)
  File "/opt/airflow/dags/data_processing_dag.py", line 38, in split_data
    raise ValueError("Nie udało się pobrać danych z XCom - brak danych.")
ValueError: Nie udało się pobrać danych z XCom - brak danych.
[2024-11-26T14:14:37.738+0000] {taskinstance.py:1318} INFO - Marking task as FAILED. dag_id=data_split_google_sheets, task_id=split_data, execution_date=20241126T140930, start_date=20241126T141437, end_date=20241126T141437
[2024-11-26T14:14:37.758+0000] {standard_task_runner.py:100} ERROR - Failed to execute job 49 for task split_data (Nie udało się pobrać danych z XCom - brak danych.; 95)
[2024-11-26T14:14:37.805+0000] {local_task_job.py:208} INFO - Task exited with return code 1
[2024-11-26T14:14:37.832+0000] {taskinstance.py:2578} INFO - 0 downstream tasks scheduled from follow-on schedule check
